Workbook
Name UPDATE: 'Data Sheet'!$E$1

Sheet Profit & Loss
A1: ='Data Sheet'!B1 -> HBL ENGINEERING LTD | H1: =UPDATE
A3: Narration | B3: ='Data Sheet'!B16 -> 42094 | C3: ='Data Sheet'!C16 -> 42460 | D3: ='Data Sheet'!D16 -> 42825 | E3: ='Data Sheet'!E16 -> 43190 | F3: ='Data Sheet'!F16 -> 43555 | G3: ='Data Sheet'!G16 -> 43921 | H3: ='Data Sheet'!H16 -> 44286 | I3: ='Data Sheet'!I16 -> 44651 | ... K3: ='Data Sheet'!K16 -> 45382 | L3: Trailing | M3: Best Case | N3: Worst Case
A4: Sales | B4: ='Data Sheet'!B17 -> 1349.28 | C4: ='Data Sheet'!C17 -> 1298.57 | D4: ='Data Sheet'!D17 -> 1414.47 | E4: ='Data Sheet'!E17 -> 1603.01 | F4: ='Data Sheet'!F17 -> 1265.88 | G4: ='Data Sheet'!G17 -> 1091.78 | H4: ='Data Sheet'!H17 -> 912.04 | I4: ='Data Sheet'!I17 -> 1236.21 | ... K4: ='Data Sheet'!K17 -> 2233.36 | L4: =SUM(Quarters!H4:K4) -> 2101.72 | M4: =$K4+M23*K4 -> 3644.312 | N4: =$K4+N23*L4 -> 2354.3984
A5: Expenses | B5: =SUM('Data Sheet'!B18,'Data Sheet'!B20:B24, -1*'Data Sheet'!B19) -> 1210.21 | C5: =SUM('Data Sheet'!C18,'Data Sheet'!C20:C24, -1*'Data Sheet'!C19) -> 1164.07 | D5: =SUM('Data Sheet'!D18,'Data Sheet'!D20:D24, -1*'Data Sheet'!D19) -> 1285.87 | E5: =SUM('Data Sheet'!E18,'Data Sheet'!E20:E24, -1*'Data Sheet'!E19) -> 1477.08 | F5: =SUM('Data Sheet'!F18,'Data Sheet'!F20:F24, -1*'Data Sheet'!F19) -> 1168.7 | G5: =SUM('Data Sheet'!G18,'Data Sheet'!G20:G24, -1*'Data Sheet'!G19) -> 1011.24 | H5: =SUM('Data Sheet'!H18,'Data Sheet'!H20:H24, -1*'Data Sheet'!H19) -> 844.67 | I5: =SUM('Data Sheet'!I18,'Data Sheet'!I20:I24, -1*'Data Sheet'!I19) -> 1097.22 | ... K5: =SUM('Data Sheet'!K18,'Data Sheet'!K20:K24, -1*'Data Sheet'!K19) -> 1809.9 | L5: =SUM(Quarters!H5:K5) -> 1657.66 | M5: =M4-M6 -> 2874.3268 | N5: =N4-N6 -> 2100.1976
A6: Operating Profit | B6: =B4-B5 -> 139.07 | C6: =C4-C5 -> 134.5 | D6: =D4-D5 -> 128.6 | E6: =E4-E5 -> 125.93 | F6: =F4-F5 -> 97.18 | G6: =G4-G5 -> 80.54 | H6: =H4-H5 -> 67.37 | I6: =I4-I5 -> 138.99 | ... K6: =K4-K5 -> 423.46 | L6: =SUM(Quarters!H6:K6) -> 444.06 | M6: =M4*M24 -> 769.98514 | N6: =N4*N24 -> 254.2008
A7: Other Income | B7: ='Data Sheet'!B25 -> 8.61 | C7: ='Data Sheet'!C25 -> 11.59 | D7: ='Data Sheet'!D25 -> 20.51 | E7: ='Data Sheet'!E25 -> 15.96 | F7: ='Data Sheet'!F25 -> 20.74 | G7: ='Data Sheet'!G25 -> 22.5 | H7: ='Data Sheet'!H25 -> 5.57 | I7: ='Data Sheet'!I25 -> 25.98 | ... K7: ='Data Sheet'!K25 -> 7.52 | L7: =SUM(Quarters!H7:K7) -> 0.76 | M7: 0 | N7: 0
A8: Depreciation | B8: ='Data Sheet'!B26 -> 52.91 | C8: ='Data Sheet'!C26 -> 50.68 | D8: ='Data Sheet'!D26 -> 48.5 | E8: ='Data Sheet'!E26 -> 46.17 | F8: ='Data Sheet'!F26 -> 44.48 | G8: ='Data Sheet'!G26 -> 40.75 | H8: ='Data Sheet'!H26 -> 38.81 | I8: ='Data Sheet'!I26 -> 35.08 | ... K8: ='Data Sheet'!K26 -> 41.26 | L8: =SUM(Quarters!H8:K8) -> 44.18 | M8: =+$L8 -> 44.18 | N8: =+$L8 -> 44.18
A9: Interest | B9: ='Data Sheet'!B27 -> 70.71 | C9: ='Data Sheet'!C27 -> 68.42 | D9: ='Data Sheet'!D27 -> 46.27 | E9: ='Data Sheet'!E27 -> 40.67 | F9: ='Data Sheet'!F27 -> 30.64 | G9: ='Data Sheet'!G27 -> 22.2 | H9: ='Data Sheet'!H27 -> 14.71 | I9: ='Data Sheet'!I27 -> 7.48 | ... K9: ='Data Sheet'!K27 -> 12.94 | L9: =SUM(Quarters!H9:K9) -> 13.5 | M9: =+$L9 -> 13.5 | N9: =+$L9 -> 13.5
A10: Profit before tax | B10: ='Data Sheet'!B28 -> 24.06 | C10: ='Data Sheet'!C28 -> 26.99 | D10: ='Data Sheet'!D28 -> 54.34 | E10: ='Data Sheet'!E28 -> 55.05 | F10: ='Data Sheet'!F28 -> 42.8 | G10: ='Data Sheet'!G28 -> 40.09 | H10: ='Data Sheet'!H28 -> 19.42 | I10: ='Data Sheet'!I28 -> 122.41 | ... K10: ='Data Sheet'!K28 -> 376.78 | L10: =SUM(Quarters!H10:K10) -> 387.14 | M10: =M6+M7-SUM(M8:M9) -> 712.30514 | N10: =N6+N7-SUM(N8:N9) -> 196.5208
A11: Tax | B11: ='Data Sheet'!B29 -> 10.32 | C11: ='Data Sheet'!C29 -> 12.16 | D11: ='Data Sheet'!D29 -> 15.95 | E11: ='Data Sheet'!E29 -> 23.37 | F11: ='Data Sheet'!F29 -> 15.07 | G11: ='Data Sheet'!G29 -> 13.87 | H11: ='Data Sheet'!H29 -> 5.7 | I11: ='Data Sheet'!I29 -> 28.69 | ... K11: ='Data Sheet'!K29 -> 96.43 | L11: =SUM(Quarters!H11:K11) -> 111.35 | M11: =IF($L10>0,$L11/$L10,0) -> 0.28762205 | N11: =IF($L10>0,$L11/$L10,0) -> 0.28762205
A12: Net profit | B12: ='Data Sheet'!B30 -> 14.22 | C12: ='Data Sheet'!C30 -> 14.9 | D12: ='Data Sheet'!D30 -> 38.66 | E12: ='Data Sheet'!E30 -> 31.63 | F12: ='Data Sheet'!F30 -> 27.73 | G12: ='Data Sheet'!G30 -> 26.22 | H12: ='Data Sheet'!H30 -> 13.73 | I12: ='Data Sheet'!I30 -> 93.9 | ... K12: ='Data Sheet'!K30 -> 280.89 | L12: =SUM(Quarters!H12:K12) -> 313.41 | M12: =M10-M11*M10 -> 507.43048 | N12: =N10-N11*N10 -> 139.99708
A13: EPS | B13: =IF('Data Sheet'!B93>0,B12/'Data Sheet'!B93,0) -> 0.56205534 | C13: =IF('Data Sheet'!C93>0,C12/'Data Sheet'!C93,0) -> 0.58893281 | D13: =IF('Data Sheet'!D93>0,D12/'Data Sheet'!D93,0) -> 1.5280632 | E13: =IF('Data Sheet'!E93>0,E12/'Data Sheet'!E93,0) -> 1.1410534 | F13: =IF('Data Sheet'!F93>0,F12/'Data Sheet'!F93,0) -> 1.0003608 | G13: =IF('Data Sheet'!G93>0,G12/'Data Sheet'!G93,0) -> 0.94588745 | H13: =IF('Data Sheet'!H93>0,H12/'Data Sheet'!H93,0) -> 0.49531025 | I13: =IF('Data Sheet'!I93>0,I12/'Data Sheet'!I93,0) -> 3.3874459 | ... K13: =IF('Data Sheet'!K93>0,K12/'Data Sheet'!K93,0) -> 10.133117 | L13: =IF('Data Sheet'!$B6>0,'Profit & Loss'!L12/'Data Sheet'!$B6,0) -> 11.314164 | M13: =IF('Data Sheet'!$B6>0,'Profit & Loss'!M12/'Data Sheet'!$B6,0) -> 18.318343 | N13: =IF('Data Sheet'!$B6>0,'Profit & Loss'!N12/'Data Sheet'!$B6,0) -> 5.053923
A14: Price to earning | B14: =IF(B15>0,B15/B13,"") -> 90.916315 | C14: =IF(C15>0,C15/C13,"") -> 61.636913 | D14: =IF(D15>0,D15/D13,"") -> 28.009312 | E14: =IF(E15>0,E15/E13,"") -> 38.692317 | F14: =IF(F15>0,F15/F13,"") -> 25.590768 | G14: =IF(G15>0,G15/G13,"") -> 11.629291 | H14: =IF(H15>0,H15/H13,"") -> 67.331537 | I14: =IF(I15>0,I15/I13,"") -> 18.716166 | ... K14: =IF(K15>0,K15/K13,"") -> 44.803589 | L14: =IF(L13>0,L15/L13,0) -> 45.756804 | M14: =M25 -> 45.756804 | N14: =N25 -> 34.010295
A15: Price | B15: ='Data Sheet'!B90 -> 51.1 | C15: ='Data Sheet'!C90 -> 36.3 | D15: ='Data Sheet'!D90 -> 42.8 | E15: ='Data Sheet'!E90 -> 44.15 | F15: ='Data Sheet'!F90 -> 25.6 | G15: ='Data Sheet'!G90 -> 11 | H15: ='Data Sheet'!H90 -> 33.35 | I15: ='Data Sheet'!I90 -> 63.4 | ... K15: ='Data Sheet'!K90 -> 454 | L15: ='Data Sheet'!B8 -> 517.7 | M15: =M13*M14 -> 838.18882 | N15: =N13*N14 -> 171.88541
A17: RATIOS:
A18: Dividend Payout | B18: =IF('Data Sheet'!B30>0, 'Data Sheet'!B31/'Data Sheet'!B30, 0) -> 0.35583685 | C18: =IF('Data Sheet'!C30>0, 'Data Sheet'!C31/'Data Sheet'!C30, 0) -> 0.42416107 | D18: =IF('Data Sheet'!D30>0, 'Data Sheet'!D31/'Data Sheet'!D30, 0) -> 0.17925504 | E18: =IF('Data Sheet'!E30>0, 'Data Sheet'!E31/'Data Sheet'!E30, 0) -> 0.2190958 | F18: =IF('Data Sheet'!F30>0, 'Data Sheet'!F31/'Data Sheet'!F30, 0) -> 0.30003606 | G18: =IF('Data Sheet'!G30>0, 'Data Sheet'!G31/'Data Sheet'!G30, 0) -> 0.31731503 | H18: =IF('Data Sheet'!H30>0, 'Data Sheet'!H31/'Data Sheet'!H30, 0) -> 0.70648216 | I18: =IF('Data Sheet'!I30>0, 'Data Sheet'!I31/'Data Sheet'!I30, 0) -> 0.11810437 | ... K18: =IF('Data Sheet'!K30>0, 'Data Sheet'!K31/'Data Sheet'!K30, 0) -> 0.049343159
A19: OPM | B19: =IF(B6>0,B6/B4,0) -> 0.10306979 | C19: =IF(C6>0,C6/C4,0) -> 0.10357547 | D19: =IF(D6>0,D6/D4,0) -> 0.090917446 | E19: =IF(E6>0,E6/E4,0) -> 0.078558462 | F19: =IF(F6>0,F6/F4,0) -> 0.07676873 | G19: =IF(G6>0,G6/G4,0) -> 0.073769441 | H19: =IF(H6>0,H6/H4,0) -> 0.073867374 | I19: =IF(I6>0,I6/I4,0) -> 0.11243235 | ... L19: =IF(L6>0,L6/L4,0) -> 0.21128409
G22: TRENDS: | H22: 10 YEARS | I22: 7 YEARS | J22: 5 YEARS | K22: 3 YEARS | L22: RECENT | M22: BEST | N22: WORST
G23: Sales Growth | H23: =IF(B4=0,"",POWER($K4/B4,1/9)-1) -> 0.05759017 | I23: =IF(D4=0,"",POWER($K4/D4,1/7)-1) -> 0.067426194 | J23: =IF(F4=0,"",POWER($K4/F4,1/5)-1) -> 0.12024558 | K23: =IF(H4=0,"",POWER($K4/H4, 1/3)-1) -> 0.34787085 | L23: =IF(ISERROR(MAX(IF(J4=0,"",(K4-J4)/J4),IF(K4=0,"",(L4-K4)/K4))),"",MAX(IF(J4=0,"",(K4-J4)/J4),IF(K4=0,"",(L4-K4)/K4))) -> 0.63176199 | M23: =MAX(K23:L23) -> 0.63176199 | N23: =MIN(H23:L23) -> 0.05759017
G24: OPM | H24: =IF(SUM(B4:$K$4)=0,"",SUMPRODUCT(B19:$K$19,B4:$K$4)/SUM(B4:$K$4)) -> 0.10796847 | I24: =IF(SUM(E4:$K$4)=0,"",SUMPRODUCT(E19:$K$19,E4:$K$4)/SUM(E4:$K$4)) -> 0.11172016 | J24: =IF(SUM(G4:$K$4)=0,"",SUMPRODUCT(G19:$K$19,G4:$K$4)/SUM(G4:$K$4)) -> 0.12595603 | K24: =IF(SUM(I4:$K$4)=0, "", SUMPRODUCT(I19:$K$19,I4:$K$4)/SUM(I4:$K$4)) -> 0.14755128 | L24: =L19 -> 0.21128409 | M24: =MAX(K24:L24) -> 0.21128409 | N24: =MIN(H24:L24) -> 0.10796847
G25: Price to Earning | H25: =IF(ISERROR(AVERAGEIF(B14:$L14,">0")),"",AVERAGEIF(B14:$L14,">0")) -> 41.80433 | I25: =IF(ISERROR(AVERAGEIF(E14:$L14,">0")),"",AVERAGEIF(E14:$L14,">0")) -> 34.910637 | J25: =IF(ISERROR(AVERAGEIF(G14:$L14,">0")),"",AVERAGEIF(G14:$L14,">0")) -> 35.833668 | K25: =IF(ISERROR(AVERAGEIF(I14:$L14,">0")),"",AVERAGEIF(I14:$L14,">0")) -> 34.010295 | L25: =L14 -> 45.756804 | M25: =MAX(K25:L25) -> 45.756804 | N25: =MIN(H25:L25) -> 34.010295

Sheet Quarters
A1: ='Profit & Loss'!A1 -> HBL ENGINEERING LTD | E1: =UPDATE
A3: Narration | B3: ='Data Sheet'!B41 -> 44834 | C3: ='Data Sheet'!C41 -> 44926 | D3: ='Data Sheet'!D41 -> 45016 | E3: ='Data Sheet'!E41 -> 45107 | F3: ='Data Sheet'!F41 -> 45199 | G3: ='Data Sheet'!G41 -> 45291 | H3: ='Data Sheet'!H41 -> 45382 | I3: ='Data Sheet'!I41 -> 45473 | ... K3: ='Data Sheet'!K41 -> 45657
A4: Sales | B4: ='Data Sheet'!B42 -> 313.88 | C4: ='Data Sheet'!C42 -> 332.49 | D4: ='Data Sheet'!D42 -> 402.61 | E4: ='Data Sheet'!E42 -> 467.43 | F4: ='Data Sheet'!F42 -> 556.58 | G4: ='Data Sheet'!G42 -> 599.26 | H4: ='Data Sheet'!H42 -> 610.09 | I4: ='Data Sheet'!I42 -> 520.11 | ... K4: ='Data Sheet'!K42 -> 450.56
A5: Expenses | B5: ='Data Sheet'!B43 -> 280.61 | C5: ='Data Sheet'!C43 -> 294.1 | D5: ='Data Sheet'!D43 -> 357.84 | E5: ='Data Sheet'!E43 -> 389.5 | F5: ='Data Sheet'!F43 -> 455.74 | G5: ='Data Sheet'!G43 -> 486.06 | H5: ='Data Sheet'!H43 -> 478.6 | I5: ='Data Sheet'!I43 -> 409.64 | ... K5: ='Data Sheet'!K43 -> 357
A6: Operating Profit | B6: ='Data Sheet'!B50 -> 33.27 | C6: ='Data Sheet'!C50 -> 38.39 | D6: ='Data Sheet'!D50 -> 44.77 | E6: ='Data Sheet'!E50 -> 77.93 | F6: ='Data Sheet'!F50 -> 100.84 | G6: ='Data Sheet'!G50 -> 113.2 | H6: ='Data Sheet'!H50 -> 131.49 | I6: ='Data Sheet'!I50 -> 110.47 | ... K6: ='Data Sheet'!K50 -> 93.56
A7: Other Income | B7: ='Data Sheet'!B44 -> 6.14 | C7: ='Data Sheet'!C44 -> 5.79 | D7: ='Data Sheet'!D44 -> 3.93 | E7: ='Data Sheet'!E44 -> 2.73 | F7: ='Data Sheet'!F44 -> 3.25 | G7: ='Data Sheet'!G44 -> 2.44 | H7: ='Data Sheet'!H44 -> -18.6 | I7: ='Data Sheet'!I44 -> 5.44 | ... K7: ='Data Sheet'!K44 -> 1.5
A8: Depreciation | B8: ='Data Sheet'!B45 -> 8.44 | C8: ='Data Sheet'!C45 -> 8.73 | D8: ='Data Sheet'!D45 -> 10.01 | E8: ='Data Sheet'!E45 -> 9.5 | F8: ='Data Sheet'!F45 -> 10.01 | G8: ='Data Sheet'!G45 -> 10.84 | H8: ='Data Sheet'!H45 -> 10.9 | I8: ='Data Sheet'!I45 -> 10.83 | ... K8: ='Data Sheet'!K45 -> 11.19
A9: Interest | B9: ='Data Sheet'!B46 -> 1.05 | C9: ='Data Sheet'!C46 -> 2.08 | D9: ='Data Sheet'!D46 -> 2.55 | E9: ='Data Sheet'!E46 -> 2.08 | F9: ='Data Sheet'!F46 -> 3.4 | G9: ='Data Sheet'!G46 -> 3.28 | H9: ='Data Sheet'!H46 -> 4.17 | I9: ='Data Sheet'!I46 -> 1.89 | ... K9: ='Data Sheet'!K46 -> 4.65
A10: Profit before tax | B10: ='Data Sheet'!B47 -> 29.92 | C10: ='Data Sheet'!C47 -> 33.37 | D10: ='Data Sheet'!D47 -> 36.14 | E10: ='Data Sheet'!E47 -> 69.08 | F10: ='Data Sheet'!F47 -> 90.68 | G10: ='Data Sheet'!G47 -> 101.52 | H10: ='Data Sheet'!H47 -> 97.82 | I10: ='Data Sheet'!I47 -> 103.19 | ... K10: ='Data Sheet'!K47 -> 79.22
A11: Tax | B11: ='Data Sheet'!B48 -> 10.39 | C11: ='Data Sheet'!C48 -> 10.73 | D11: ='Data Sheet'!D48 -> 1.2 | E11: ='Data Sheet'!E48 -> 17.57 | F11: ='Data Sheet'!F48 -> 23.52 | G11: ='Data Sheet'!G48 -> 23.07 | H11: ='Data Sheet'!H48 -> 32.29 | I11: ='Data Sheet'!I48 -> 27.33 | ... K11: ='Data Sheet'!K48 -> 20.83
A12: Net profit | B12: ='Data Sheet'!B49 -> 20.08 | C12: ='Data Sheet'!C49 -> 23.74 | D12: ='Data Sheet'!D49 -> 34.8 | E12: ='Data Sheet'!E49 -> 51.73 | F12: ='Data Sheet'!F49 -> 68.67 | G12: ='Data Sheet'!G49 -> 79.04 | H12: ='Data Sheet'!H49 -> 81.45 | I12: ='Data Sheet'!I49 -> 80.09 | ... K12: ='Data Sheet'!K49 -> 64.61
A14: OPM | B14: =IF(B4>0,B6/B4,"") -> 0.10599592 | C14: =IF(C4>0,C6/C4,"") -> 0.11546212 | D14: =IF(D4>0,D6/D4,"") -> 0.11119942 | E14: =IF(E4>0,E6/E4,"") -> 0.16672015 | F14: =IF(F4>0,F6/F4,"") -> 0.18117791 | G14: =IF(G4>0,G6/G4,"") -> 0.18889964 | H14: =IF(H4>0,H6/H4,"") -> 0.21552558 | I14: =IF(I4>0,I6/I4,"") -> 0.21239738 | ... K14: =IF(K4>0,K6/K4,"") -> 0.2076527

Sheet Balance Sheet
A1: ='Profit & Loss'!A1 -> HBL ENGINEERING LTD | E1: =UPDATE
A3: Narration | B3: ='Data Sheet'!B56 -> 42094 | C3: ='Data Sheet'!C56 -> 42460 | D3: ='Data Sheet'!D56 -> 42825 | E3: ='Data Sheet'!E56 -> 43190 | F3: ='Data Sheet'!F56 -> 43555 | G3: ='Data Sheet'!G56 -> 43921 | H3: ='Data Sheet'!H56 -> 44286 | I3: ='Data Sheet'!I56 -> 44651 | ... K3: ='Data Sheet'!K56 -> 45382
A4: Equity Share Capital | B4: ='Data Sheet'!B57 -> 25.3 | C4: ='Data Sheet'!C57 -> 25.3 | D4: ='Data Sheet'!D57 -> 27.72 | E4: ='Data Sheet'!E57 -> 27.72 | F4: ='Data Sheet'!F57 -> 27.72 | G4: ='Data Sheet'!G57 -> 27.72 | H4: ='Data Sheet'!H57 -> 27.72 | I4: ='Data Sheet'!I57 -> 27.72 | ... K4: ='Data Sheet'!K57 -> 27.72
A5: Reserves | B5: ='Data Sheet'!B58 -> 539.48 | C5: ='Data Sheet'!C58 -> 583.81 | D5: ='Data Sheet'!D58 -> 701.4 | E5: ='Data Sheet'!E58 -> 723.97 | F5: ='Data Sheet'!F58 -> 738.51 | G5: ='Data Sheet'!G58 -> 745.15 | H5: ='Data Sheet'!H58 -> 754.33 | I5: ='Data Sheet'!I58 -> 838.04 | ... K5: ='Data Sheet'!K58 -> 1192.82
A6: Borrowings | B6: ='Data Sheet'!B59 -> 686.46 | C6: ='Data Sheet'!C59 -> 548.9 | D6: ='Data Sheet'!D59 -> 479.03 | E6: ='Data Sheet'!E59 -> 366.28 | F6: ='Data Sheet'!F59 -> 232.1 | G6: ='Data Sheet'!G59 -> 160.96 | H6: ='Data Sheet'!H59 -> 69.94 | I6: ='Data Sheet'!I59 -> 62.61 | ... K6: ='Data Sheet'!K59 -> 67.46
A7: Other Liabilities | B7: ='Data Sheet'!B60 -> 310.72 | C7: ='Data Sheet'!C60 -> 276.89 | D7: ='Data Sheet'!D60 -> 258.38 | E7: ='Data Sheet'!E60 -> 223.55 | F7: ='Data Sheet'!F60 -> 162.38 | G7: ='Data Sheet'!G60 -> 168.69 | H7: ='Data Sheet'!H60 -> 184.27 | I7: ='Data Sheet'!I60 -> 204.24 | ... K7: ='Data Sheet'!K60 -> 366.1
A8: Total | B8: ='Data Sheet'!B61 -> 1561.96 | C8: ='Data Sheet'!C61 -> 1434.9 | D8: ='Data Sheet'!D61 -> 1466.53 | E8: ='Data Sheet'!E61 -> 1341.52 | F8: ='Data Sheet'!F61 -> 1160.71 | G8: ='Data Sheet'!G61 -> 1102.52 | H8: ='Data Sheet'!H61 -> 1036.26 | I8: ='Data Sheet'!I61 -> 1132.61 | ... K8: ='Data Sheet'!K61 -> 1654.1
A10: Net Block | B10: ='Data Sheet'!B62 -> 456.4 | C10: ='Data Sheet'!C62 -> 415.4 | D10: ='Data Sheet'!D62 -> 416.88 | E10: ='Data Sheet'!E62 -> 363.43 | F10: ='Data Sheet'!F62 -> 320.7 | G10: ='Data Sheet'!G62 -> 303.69 | H10: ='Data Sheet'!H62 -> 279.01 | I10: ='Data Sheet'!I62 -> 264.51 | ... K10: ='Data Sheet'!K62 -> 354.24
A11: Capital Work in Progress | B11: ='Data Sheet'!B63 -> 49.38 | C11: ='Data Sheet'!C63 -> 48.07 | D11: ='Data Sheet'!D63 -> 33.36 | E11: ='Data Sheet'!E63 -> 26.01 | F11: ='Data Sheet'!F63 -> 37.21 | G11: ='Data Sheet'!G63 -> 26.96 | H11: ='Data Sheet'!H63 -> 42.86 | I11: ='Data Sheet'!I63 -> 81.33 | ... K11: ='Data Sheet'!K63 -> 20.4
A12: Investments | B12: ='Data Sheet'!B64 -> 1.99 | C12: ='Data Sheet'!C64 -> 7.7 | D12: ='Data Sheet'!D64 -> 7.85 | E12: ='Data Sheet'!E64 -> 4.73 | F12: ='Data Sheet'!F64 -> 5.31 | G12: ='Data Sheet'!G64 -> 6.06 | H12: ='Data Sheet'!H64 -> 7.07 | I12: ='Data Sheet'!I64 -> 7.73 | ... K12: ='Data Sheet'!K64 -> 108.22
A13: Other Assets | B13: ='Data Sheet'!B65 -> 1054.19 | C13: ='Data Sheet'!C65 -> 963.73 | D13: ='Data Sheet'!D65 -> 1008.44 | E13: ='Data Sheet'!E65 -> 947.35 | F13: ='Data Sheet'!F65 -> 797.49 | G13: ='Data Sheet'!G65 -> 765.81 | H13: ='Data Sheet'!H65 -> 707.32 | I13: ='Data Sheet'!I65 -> 779.04 | ... K13: ='Data Sheet'!K65 -> 1171.24
A14: Total | B14: ='Data Sheet'!B66 -> 1561.96 | C14: ='Data Sheet'!C66 -> 1434.9 | D14: ='Data Sheet'!D66 -> 1466.53 | E14: ='Data Sheet'!E66 -> 1341.52 | F14: ='Data Sheet'!F66 -> 1160.71 | G14: ='Data Sheet'!G66 -> 1102.52 | H14: ='Data Sheet'!H66 -> 1036.26 | I14: ='Data Sheet'!I66 -> 1132.61 | ... K14: ='Data Sheet'!K66 -> 1654.1
A16: Working Capital | B16: =B13-B7 -> 743.47 | C16: =C13-C7 -> 686.84 | D16: =D13-D7 -> 750.06 | E16: =E13-E7 -> 723.8 | F16: =F13-F7 -> 635.11 | G16: =G13-G7 -> 597.12 | H16: =H13-H7 -> 523.05 | I16: =I13-I7 -> 574.8 | ... K16: =K13-K7 -> 805.14
A17: Debtors | B17: ='Data Sheet'!B67 -> 393.64 | C17: ='Data Sheet'!C67 -> 426.62 | D17: ='Data Sheet'!D67 -> 471.03 | E17: ='Data Sheet'!E67 -> 453.18 | F17: ='Data Sheet'!F67 -> 363.09 | G17: ='Data Sheet'!G67 -> 305.16 | H17: ='Data Sheet'!H67 -> 253.72 | I17: ='Data Sheet'!I67 -> 292.66 | ... K17: ='Data Sheet'!K67 -> 382.13
A18: Inventory | B18: ='Data Sheet'!B68 -> 517.89 | C18: ='Data Sheet'!C68 -> 395.88 | D18: ='Data Sheet'!D68 -> 407.72 | E18: ='Data Sheet'!E68 -> 367.46 | F18: ='Data Sheet'!F68 -> 324.85 | G18: ='Data Sheet'!G68 -> 304.32 | H18: ='Data Sheet'!H68 -> 289.86 | I18: ='Data Sheet'!I68 -> 307.03 | ... K18: ='Data Sheet'!K68 -> 432.72
A20: Debtor Days | B20: =IF('Profit & Loss'!B4>0,'Balance Sheet'!B17/('Profit & Loss'!B4/365),0) -> 106.48538 | C20: =IF('Profit & Loss'!C4>0,'Balance Sheet'!C17/('Profit & Loss'!C4/365),0) -> 119.91367 | D20: =IF('Profit & Loss'!D4>0,'Balance Sheet'!D17/('Profit & Loss'!D4/365),0) -> 121.54797 | E20: =IF('Profit & Loss'!E4>0,'Balance Sheet'!E17/('Profit & Loss'!E4/365),0) -> 103.18757 | F20: =IF('Profit & Loss'!F4>0,'Balance Sheet'!F17/('Profit & Loss'!F4/365),0) -> 104.69227 | G20: =IF('Profit & Loss'!G4>0,'Balance Sheet'!G17/('Profit & Loss'!G4/365),0) -> 102.02 | H20: =IF('Profit & Loss'!H4>0,'Balance Sheet'!H17/('Profit & Loss'!H4/365),0) -> 101.53919 | I20: =IF('Profit & Loss'!I4>0,'Balance Sheet'!I17/('Profit & Loss'!I4/365),0) -> 86.409995 | ... K20: =IF('Profit & Loss'!K4>0,'Balance Sheet'!K17/('Profit & Loss'!K4/365),0) -> 62.451844
A21: Inventory Turnover | B21: =IF('Balance Sheet'!B18>0,'Profit & Loss'!B4/'Balance Sheet'!B18,0) -> 2.6053409 | C21: =IF('Balance Sheet'!C18>0,'Profit & Loss'!C4/'Balance Sheet'!C18,0) -> 3.2802112 | D21: =IF('Balance Sheet'!D18>0,'Profit & Loss'!D4/'Balance Sheet'!D18,0) -> 3.4692191 | E21: =IF('Balance Sheet'!E18>0,'Profit & Loss'!E4/'Balance Sheet'!E18,0) -> 4.3624068 | F21: =IF('Balance Sheet'!F18>0,'Profit & Loss'!F4/'Balance Sheet'!F18,0) -> 3.8968139 | G21: =IF('Balance Sheet'!G18>0,'Profit & Loss'!G4/'Balance Sheet'!G18,0) -> 3.5876052 | H21: =IF('Balance Sheet'!H18>0,'Profit & Loss'!H4/'Balance Sheet'!H18,0) -> 3.1464845 | I21: =IF('Balance Sheet'!I18>0,'Profit & Loss'!I4/'Balance Sheet'!I18,0) -> 4.0263492 | ... K21: =IF('Balance Sheet'!K18>0,'Profit & Loss'!K4/'Balance Sheet'!K18,0) -> 5.1612128
A23: Return on Equity | B23: =IF(SUM('Balance Sheet'!B4:B5)>0,'Profit & Loss'!B12/SUM('Balance Sheet'!B4:B5),"") -> 0.025177945 | C23: =IF(SUM('Balance Sheet'!C4:C5)>0,'Profit & Loss'!C12/SUM('Balance Sheet'!C4:C5),"") -> 0.02446192 | D23: =IF(SUM('Balance Sheet'!D4:D5)>0,'Profit & Loss'!D12/SUM('Balance Sheet'!D4:D5),"") -> 0.053022822 | E23: =IF(SUM('Balance Sheet'!E4:E5)>0,'Profit & Loss'!E12/SUM('Balance Sheet'!E4:E5),"") -> 0.042078516 | F23: =IF(SUM('Balance Sheet'!F4:F5)>0,'Profit & Loss'!F12/SUM('Balance Sheet'!F4:F5),"") -> 0.036190178 | G23: =IF(SUM('Balance Sheet'!G4:G5)>0,'Profit & Loss'!G12/SUM('Balance Sheet'!G4:G5),"") -> 0.033925498 | H23: =IF(SUM('Balance Sheet'!H4:H5)>0,'Profit & Loss'!H12/SUM('Balance Sheet'!H4:H5),"") -> 0.017556422 | I23: =IF(SUM('Balance Sheet'!I4:I5)>0,'Profit & Loss'!I12/SUM('Balance Sheet'!I4:I5),"") -> 0.10845962 | ... K23: =IF(SUM('Balance Sheet'!K4:K5)>0,'Profit & Loss'!K12/SUM('Balance Sheet'!K4:K5),"") -> 0.23013584
A24: Return on Capital Emp | C24: =IF((B4+B5+B6+C4+C5+C6)>0,('Profit & Loss'!C10+'Profit & Loss'!C9)*2/(B4+B5+B6+C4+C5+C6),"") -> 0.079203071 | D24: =IF((C4+C5+C6+D4+D5+D6)>0,('Profit & Loss'!D10+'Profit & Loss'!D9)*2/(C4+C5+C6+D4+D5+D6),"") -> 0.085040741 | E24: =IF((D4+D5+D6+E4+E5+E6)>0,('Profit & Loss'!E10+'Profit & Loss'!E9)*2/(D4+D5+D6+E4+E5+E6),"") -> 0.082300139 | F24: =IF((E4+E5+E6+F4+F5+F6)>0,('Profit & Loss'!F10+'Profit & Loss'!F9)*2/(E4+E5+E6+F4+F5+F6),"") -> 0.069404149 | G24: =IF((F4+F5+F6+G4+G5+G6)>0,('Profit & Loss'!G10+'Profit & Loss'!G9)*2/(F4+F5+F6+G4+G5+G6),"") -> 0.064477062 | H24: =IF((G4+G5+G6+H4+H5+H6)>0,('Profit & Loss'!H10+'Profit & Loss'!H9)*2/(G4+G5+G6+H4+H5+H6),"") -> 0.038223337 | I24: =IF((H4+H5+H6+I4+I5+I6)>0,('Profit & Loss'!I10+'Profit & Loss'!I9)*2/(H4+H5+H6+I4+I5+I6),"") -> 0.14591431 | J24: =IF((I4+I5+I6+J4+J5+J6)>0,('Profit & Loss'!J10+'Profit & Loss'!J9)*2/(I4+I5+I6+J4+J5+J6),"") -> 0.13871933 | K24: =IF((J4+J5+J6+K4+K5+K6)>0,('Profit & Loss'!K10+'Profit & Loss'!K9)*2/(J4+J5+J6+K4+K5+K6),"") -> 0.33517525
C26: =C16-B16 -> -56.63 | D26: =D16-C16 -> 63.22 | E26: =E16-D16 -> -26.26 | F26: =F16-E16 -> -88.69 | G26: =G16-F16 -> -37.99 | H26: =H16-G16 -> -74.07 | I26: =I16-H16 -> 51.75 | J26: =J16-I16 -> 83.45 | K26: =K16-J16 -> 146.89 | L26: =AVERAGE(D26:K26) -> 14.7875

Sheet Cash Flow
A1: ='Balance Sheet'!A1 -> HBL ENGINEERING LTD | E1: =UPDATE
A3: Narration | B3: ='Data Sheet'!B81 -> 42094 | C3: ='Data Sheet'!C81 -> 42460 | D3: ='Data Sheet'!D81 -> 42825 | E3: ='Data Sheet'!E81 -> 43190 | F3: ='Data Sheet'!F81 -> 43555 | G3: ='Data Sheet'!G81 -> 43921 | H3: ='Data Sheet'!H81 -> 44286 | I3: ='Data Sheet'!I81 -> 44651 | ... K3: ='Data Sheet'!K81 -> 45382
A4: Cash from Operating Activity | B4: ='Data Sheet'!B82 -> 78.89 | C4: ='Data Sheet'!C82 -> 157.76 | D4: ='Data Sheet'!D82 -> 43.2 | E4: ='Data Sheet'!E82 -> 158.76 | F4: ='Data Sheet'!F82 -> 167.07 | G4: ='Data Sheet'!G82 -> 148.78 | H4: ='Data Sheet'!H82 -> 121.12 | I4: ='Data Sheet'!I82 -> 62.47 | ... K4: ='Data Sheet'!K82 -> 273.1
A5: Cash from Investing Activity | B5: ='Data Sheet'!B83 -> -12.73 | C5: ='Data Sheet'!C83 -> -10.2 | D5: ='Data Sheet'!D83 -> 60.23 | E5: ='Data Sheet'!E83 -> -7.97 | F5: ='Data Sheet'!F83 -> 0.92 | G5: ='Data Sheet'!G83 -> -5.73 | H5: ='Data Sheet'!H83 -> -32.02 | I5: ='Data Sheet'!I83 -> -16.77 | ... K5: ='Data Sheet'!K83 -> -139.38
A6: Cash from Financing Activity | B6: ='Data Sheet'!B84 -> -66.23 | C6: ='Data Sheet'!C84 -> -152.55 | D6: ='Data Sheet'!D84 -> -114.38 | E6: ='Data Sheet'!E84 -> -149.5 | F6: ='Data Sheet'!F84 -> -163.41 | G6: ='Data Sheet'!G84 -> -114.04 | H6: ='Data Sheet'!H84 -> -103.55 | I6: ='Data Sheet'!I84 -> -22.32 | ... K6: ='Data Sheet'!K84 -> -42.27
A7: Net Cash Flow | B7: ='Data Sheet'!B85 -> -0.07 | C7: ='Data Sheet'!C85 -> -4.99 | D7: ='Data Sheet'!D85 -> -10.94 | E7: ='Data Sheet'!E85 -> 1.29 | F7: ='Data Sheet'!F85 -> 4.58 | G7: ='Data Sheet'!G85 -> 29.01 | H7: ='Data Sheet'!H85 -> -14.45 | I7: ='Data Sheet'!I85 -> 23.38 | ... K7: ='Data Sheet'!K85 -> 91.45

Sheet Data Sheet
A1: COMPANY NAME | B1: HBL ENGINEERING LTD | E1: =IF(B2<>B3, "A NEW VERSION OF THE WORKSHEET IS AVAILABLE", "")
A2: LATEST VERSION | B2: 2.1
A3: CURRENT VERSION | B3: 2.1
A5: META
A6: Number of shares | B6: =IF(B9>0, B9/B8, 0) -> 27.700676
A7: Face Value | B7: 1
A8: Current Price | B8: 517.7
A9: Market Capitalization | B9: 14340.64
A15: PROFIT & LOSS
A16: Report Date | B16: 42094 | C16: 42460 | D16: 42825 | E16: 43190 | F16: 43555 | G16: 43921 | H16: 44286 | I16: 44651 | J16: 45016 | K16: 45382
A17: Sales | B17: 1349.28 | C17: 1298.57 | D17: 1414.47 | E17: 1603.01 | F17: 1265.88 | G17: 1091.78 | H17: 912.04 | I17: 1236.21 | J17: 1368.68 | K17: 2233.36
A18: Raw Material Cost | B18: 768.91 | C18: 770.36 | D18: 898.26 | E18: 1029.99 | F18: 809.02 | G18: 677.72 | H18: 555.67 | I18: 760.64 | J18: 832.09 | K18: 1208.52
A19: Change in Inventory | B19: -66.12 | C19: -9.75 | D19: 12.09 | E19: -34.88 | F19: -6.67 | G19: -9.53 | H19: -7.29 | I19: 7.48 | J19: -0.64 | K19: 58.79
A20: Power and Fuel | B20: 58.46 | C20: 51.62 | D20: 52.81 | E20: 61.88 | F20: 53.55 | G20: 45.64 | H20: 36.53 | I20: 42.44 | J20: 49.02 | K20: 62.17
A21: Other Mfr. Exp | B21: 103.62 | C21: 116.46 | D21: 123.38 | E21: 132.4 | F21: 104.71 | G21: 97.6 | H21: 88.08 | I21: 111.08 | J21: 119.89 | K21: 298.95
A22: Employee Cost | B22: 99.12 | C22: 103.81 | D22: 99.68 | E22: 97.96 | F22: 87.45 | G22: 90.7 | H22: 82.18 | I22: 99.91 | J22: 110.38 | K22: 157.62
A23: Selling and admin | B23: 94.93 | C23: 82.64 | D23: 93.49 | E23: 91.83 | F23: 86.31 | G23: 72.11 | H23: 54.54 | I23: 67.22 | J23: 79.48 | K23: 100.76
A24: Other Expenses | B24: 19.05 | C24: 29.43 | D24: 30.34 | E24: 28.14 | F24: 20.99 | G24: 17.94 | H24: 20.38 | I24: 23.41 | J24: 25.74 | K24: 40.67
A25: Other Income | B25: 8.61 | C25: 11.59 | D25: 20.51 | E25: 15.96 | F25: 20.74 | G25: 22.5 | H25: 5.57 | I25: 25.98 | J25: 20.37 | K25: 7.52
A26: Depreciation | B26: 52.91 | C26: 50.68 | D26: 48.5 | E26: 46.17 | F26: 44.48 | G26: 40.75 | H26: 38.81 | I26: 35.08 | J26: 35.46 | K26: 41.26
A27: Interest | B27: 70.71 | C27: 68.42 | D27: 46.27 | E27: 40.67 | F27: 30.64 | G27: 22.2 | H27: 14.71 | I27: 7.48 | J27: 6.55 | K27: 12.94
... A31: Dividend Amount | B31: 5.06 | C31: 6.32 | D31: 6.93 | E31: 6.93 | F31: 8.32 | G31: 8.32 | H31: 9.7 | I31: 11.09 | J31: 12.47 | K31: 13.86
I33: =SUM(I18:I22) -> 1021.55 | J33: =SUM(J18:J22) -> 1110.74 | K33: =SUM(K18:K22) -> 1786.05
I34: =SUM(I23:I24) -> 90.63 | J34: =SUM(J23:J24) -> 105.22 | K34: =SUM(K23:K24) -> 141.43
I35: =I33+I34 -> 1112.18 | J35: =J33+J34 -> 1215.96 | K35: =K33+K34 -> 1927.48
A40: Quarters
A41: Report Date | B41: 44834 | C41: 44926 | D41: 45016 | E41: 45107 | F41: 45199 | G41: 45291 | H41: 45382 | I41: 45473 | J41: 45565 | K41: 45657
A42: Sales | B42: 313.88 | C42: 332.49 | D42: 402.61 | E42: 467.43 | F42: 556.58 | G42: 599.26 | H42: 610.09 | I42: 520.11 | J42: 520.96 | K42: 450.56
A43: Expenses | B43: 280.61 | C43: 294.1 | D43: 357.84 | E43: 389.5 | F43: 455.74 | G43: 486.06 | H43: 478.6 | I43: 409.64 | J43: 412.42 | K43: 357
A44: Other Income | B44: 6.14 | C44: 5.79 | D44: 3.93 | E44: 2.73 | F44: 3.25 | G44: 2.44 | H44: -18.6 | I44: 5.44 | J44: 12.42 | K44: 1.5
A45: Depreciation | B45: 8.44 | C45: 8.73 | D45: 10.01 | E45: 9.5 | F45: 10.01 | G45: 10.84 | H45: 10.9 | I45: 10.83 | J45: 11.26 | K45: 11.19
A46: Interest | B46: 1.05 | C46: 2.08 | D46: 2.55 | E46: 2.08 | F46: 3.4 | G46: 3.28 | H46: 4.17 | I46: 1.89 | J46: 2.79 | K46: 4.65
A47: Profit before tax | B47: 29.92 | C47: 33.37 | D47: 36.14 | E47: 69.08 | F47: 90.68 | G47: 101.52 | H47: 97.82 | I47: 103.19 | J47: 106.91 | K47: 79.22
A48: Tax | B48: 10.39 | C48: 10.73 | D48: 1.2 | E48: 17.57 | F48: 23.52 | G48: 23.07 | H48: 32.29 | I48: 27.33 | J48: 30.9 | K48: 20.83
A49: Net profit | B49: 20.08 | C49: 23.74 | D49: 34.8 | E49: 51.73 | F49: 68.67 | G49: 79.04 | H49: 81.45 | I49: 80.09 | J49: 87.26 | K49: 64.61
A50: Operating Profit | B50: 33.27 | C50: 38.39 | D50: 44.77 | E50: 77.93 | F50: 100.84 | G50: 113.2 | H50: 131.49 | I50: 110.47 | J50: 108.54 | K50: 93.56
A55: BALANCE SHEET
A56: Report Date | B56: 42094 | C56: 42460 | D56: 42825 | E56: 43190 | F56: 43555 | G56: 43921 | H56: 44286 | I56: 44651 | J56: 45016 | K56: 45382
A57: Equity Share Capital | B57: 25.3 | C57: 25.3 | D57: 27.72 | E57: 27.72 | F57: 27.72 | G57: 27.72 | H57: 27.72 | I57: 27.72 | J57: 27.72 | K57: 27.72
A58: Reserves | B58: 539.48 | C58: 583.81 | D58: 701.4 | E58: 723.97 | F58: 738.51 | G58: 745.15 | H58: 754.33 | I58: 838.04 | J58: 923.73 | K58: 1192.82
...

Sheet Valuation
A1: (INR in crores, Financial Year March 31)
A2: Operating Scenario
D3: Historical Period | I3: Forecasted Period
D4: =+E4-1 -> 2022 | E4: 2023 | F4: 2024 | H4: 2025 | I4: 2026 | J4: 2027 | K4: 2028 | L4: 2029 | M4: 2030
A5: Sales | D5: ='Profit & Loss'!I4 -> 1236.21 | E5: ='Profit & Loss'!J4 -> 1368.68 | F5: ='Profit & Loss'!K4 -> 2233.36 | H5: =F5*(1+H6) -> 2255.6936 | I5: =H5*(1+I6) -> 2932.4017 | J5: =I5*(1+J6) -> 3518.882 | K5: =J5*(1+K6) -> 4222.6584 | L5: =K5*(1+L6) -> 4476.0179 | M5: =L5*(1+M6) -> 4744.579
A6: % growth | E6: =(E5-D5)/D5 -> 0.10715817 | F6: =(F5-E5)/E5 -> 0.63176199 | H6: =0.01 -> 0.01 | I6: =0.3 -> 0.3 | J6: =0.2 -> 0.2 | K6: =0.2 -> 0.2 | L6: =0.06 -> 0.06 | M6: =0.06 -> 0.06
A7: Cost of Goods Sold | C7: 0.8 | D7: ='Data Sheet'!I33 -> 1021.55 | E7: ='Data Sheet'!J33 -> 1110.74 | F7: ='Data Sheet'!K33 -> 1786.05 | H7: =H5*0.8 -> 1804.5549 | I7: =I5*0.8 -> 2345.9213 | J7: =J5*0.8 -> 2815.1056 | K7: =K5*0.8 -> 3378.1267 | L7: =L5*0.8 -> 3580.8143 | M7: =M5*0.8 -> 3795.6632
A8: Gross Profit | D8: =+D5-D7 -> 214.66 | E8: =+E5-E7 -> 257.94 | F8: =+F5-F7 -> 447.31 | H8: =+H5-H7 -> 451.13872 | I8: =+I5-I7 -> 586.48034 | J8: =+J5-J7 -> 703.7764 | K8: =+K5-K7 -> 844.53168 | L8: =+L5-L7 -> 895.20358 | M8: =+M5-M7 -> 948.9158
A9: % margin | D9: =D8/D5 -> 0.17364364 | E9: =E8/E5 -> 0.18845895 | F9: =F8/F5 -> 0.20028567 | H9: =H8/H5 -> 0.2 | I9: =I8/I5 -> 0.2 | J9: =J8/J5 -> 0.2 | K9: =K8/K5 -> 0.2 | L9: =L8/L5 -> 0.2 | M9: =M8/M5 -> 0.2
A10: Selling, General & Administrative | C10: 0.07 | D10: ='Data Sheet'!I34 -> 90.63 | E10: ='Data Sheet'!J34 -> 105.22 | F10: ='Data Sheet'!K34 -> 141.43 | H10: =H5*0.07 -> 157.89855 | I10: =I5*0.07 -> 205.26812 | J10: =J5*0.07 -> 246.32174 | K10: =K5*0.07 -> 295.58609 | L10: =L5*0.07 -> 313.32125 | M10: =M5*0.07 -> 332.12053
A11: EBITDA | D11: =D8-D10 -> 124.03 | E11: =E8-E10 -> 152.72 | F11: =F8-F10 -> 305.88 | H11: =H8-H10 -> 293.24017 | I11: =I8-I10 -> 381.21222 | J11: =J8-J10 -> 457.45466 | K11: =K8-K10 -> 548.94559 | L11: =L8-L10 -> 581.88233 | M11: =M8-M10 -> 616.79527
A12: % margin | D12: =D11/D5 -> 0.10033085 | E12: =E11/E5 -> 0.11158196 | F12: =F11/F5 -> 0.13695956 | H12: =H11/H5 -> 0.13 | I12: =I11/I5 -> 0.13 | J12: =J11/J5 -> 0.13 | K12: =K11/K5 -> 0.13 | L12: =L11/L5 -> 0.13 | M12: =M11/M5 -> 0.13
A13: Depreciation & Amortization | C13: 0.02 | D13: ='Data Sheet'!I26 -> 35.08 | E13: ='Data Sheet'!J26 -> 35.46 | F13: ='Data Sheet'!K26 -> 41.26 | H13: =F13*1.02 -> 42.0852 | I13: =H13*1.02 -> 42.926904 | J13: =I13*1.02 -> 43.785442 | K13: =J13*1.02 -> 44.661151 | L13: =K13*1.02 -> 45.554374 | M13: =L13*1.02 -> 46.465461
A14: EBIT | D14: =+D11-D13 -> 88.95 | E14: =+E11-E13 -> 117.26 | F14: =+F11-F13 -> 264.62 | H14: =+H11-H13 -> 251.15497 | I14: =+I11-I13 -> 338.28531 | J14: =+J11-J13 -> 413.66922 | K14: =+K11-K13 -> 504.28444 | L14: =+L11-L13 -> 536.32796 | M14: =+M11-M13 -> 570.32981
A15: % margin | D15: =D14/D5 -> 0.071953794 | E15: =E14/E5 -> 0.085673788 | F15: =F14/F5 -> 0.11848515 | H15: =H14/H5 -> 0.11134268 | I15: =I14/I5 -> 0.11536118 | J15: =J14/J5 -> 0.117557 | K15: =K14/K5 -> 0.11942345 | L15: =L14/L5 -> 0.11982257 | M15: =M14/M5 -> 0.12020662
A16: Taxes | C16: 0.3 | D16: =D14*$C$16 -> 26.685 | E16: =E14*$C$16 -> 35.178 | F16: =F14*$C$16 -> 79.386 | H16: =H14*$C$16 -> 75.34649 | I16: =I14*$C$16 -> 101.48559 | J16: =J14*$C$16 -> 124.10077 | K16: =K14*$C$16 -> 151.28533 | L16: =L14*$C$16 -> 160.89839 | M16: =M14*$C$16 -> 171.09894
A17: EBIT(1-T) | D17: =D14*(1-$C$16) -> 62.265 | E17: =E14*(1-$C$16) -> 82.082 | F17: =F14*(1-$C$16) -> 185.234 | H17: =+H14-H16 -> 175.80848 | I17: =+I14-I16 -> 236.79972 | J17: =+J14-J16 -> 289.56845 | K17: =+K14-K16 -> 352.99911 | L17: =+L14-L16 -> 375.42957 | M17: =+M14-M16 -> 399.23087
A19: Plus: Depreciation & Amortization | D19: =D13 -> 35.08 | E19: =E13 -> 35.46 | F19: =F13 -> 41.26 | H19: =H13 -> 42.0852 | I19: =I13 -> 42.926904 | J19: =J13 -> 43.785442 | K19: =K13 -> 44.661151 | L19: =L13 -> 45.554374 | M19: =M13 -> 46.465461
A20: Less: Capital Expenditures | D20: ='Balance Sheet'!I11 -> 81.33 | E20: ='Balance Sheet'!J11 -> 50.09 | F20: ='Balance Sheet'!K11 -> 20.4 | H20: =40 -> 40 | I20: =H20 -> 40 | J20: =H20 -> 40 | K20: =I20 -> 40 | L20: =J20 -> 40 | M20: =K20 -> 40
A21: Less: Inc./(Dec.) in Net Working Capital | D21: ='Balance Sheet'!I26 -> 51.75 | E21: ='Balance Sheet'!J26 -> 83.45 | F21: ='Balance Sheet'!K26 -> 146.89 | H21: 99.78619 | I21: 117.15385 | J21: 134.52152 | K21: 151.88918 | L21: 169.25684 | M21: 186.62451
A23: Unlevered Free Cash Flow | D23: =+D17+SUM(D19:D21) -> 230.425 | E23: =+E17+SUM(E19:E21) -> 251.082 | F23: =+F17+SUM(F19:F21) -> 393.784 | H23: =+H17+SUM(H19:H21) -> 357.67987 | I23: =+I17+SUM(I19:I21) -> 436.88048 | J23: =+J17+SUM(J19:J21) -> 507.87541 | K23: =+K17+SUM(K19:K21) -> 589.54944 | L23: =+L17+SUM(L19:L21) -> 630.24079 | M23: =+M17+SUM(M19:M21) -> 672.32083
A24: WACC | D24: =C35 -> 0.098464152
A25: Discount Period | H25: 1 | I25: 2 | J25: 3 | K25: 4 | L25: 5 | M25: 6
A26: Discount Factor | H26: =1/((1+$D$24)^(H25)) -> 0.91036198 | I26: =1/((1+$D$24)^(I25)) -> 0.82875893 | J26: =1/((1+$D$24)^(J25)) -> 0.75447062 | K26: =1/((1+$D$24)^(K25)) -> 0.68684137 | L26: =1/((1+$D$24)^(L25)) -> 0.62527427 | M26: =1/((1+$D$24)^(M25)) -> 0.56922592
A27: Present Value of Free Cash Flow | H27: =+H23*H26 -> 325.61815 | I27: =+I23*I26 -> 362.0686 | J27: =+J23*J26 -> 383.17708 | K27: =+K23*K26 -> 404.92695 | L27: =+L23*L26 -> 394.07335 | M27: =+M23*M26 -> 382.70245
C29: WACC Calculation
A31: Risk Free rate of Return -Rf | C31: 0.06 | D31: Beta | F31: 0.73
A32: Risk Premium - Rm-Rf | C32: =11%-C31 -> 0.05 | D32: Cost of debt post tax-Kd | F32: ='Data Sheet'!K27*(1-0.3)/'Data Sheet'!K59 -> 0.13427216
A33: Weight of Debt -Wd | C33: =5.2% -> 0.052 | D33: Weight of Equity-We | F33: =1-C33 -> 0.948
A34: Cost of Equity-CAPM | C34: =C31+(F31*C32) -> 0.0965
A35: Cost of Capital-WACC | C35: =(C33*F32)+(F33*C34) -> 0.098464152
A38: Enterprise Value | F38: Equity Value and Share Price | K38: Perpetuity Growth Rate
A39: Total Value Of NPV of Cash flows | D39: =+SUM(H27:M27) -> 2252.5666 | F39: Enterprise Value | I39: =+D48 -> 18706.035 | K39: ="Terminal Year Free Cash Flow ("&M4&"E)" -> Terminal Year Free Cash Flow (2030E) | N39: =+M23 -> 672.32083
F40: Less: Total Debt | I40: ='Balance Sheet'!K6 -> 67.46 | K40: WACC | N40: =+D24 -> 0.098464152
B41: Terminal Value ( Exit Multiple) | F41: Less: Noncontrolling Interest | I41: =-1 -> -1 | K41: Terminal Value | N41: =+D44 -> 28904.989
A42: ="Terminal Year EBITDA ("&M4&"E)" -> Terminal Year EBITDA (2030E) | D42: =+M11 -> 616.79527 | F42: Plus: Cash and Cash Equivalents | I42: ='Data Sheet'!K69 -> 234.95
A43: Exit Multiple | D43: =N49 -> 46.863182 | K43: Implied Perpetuity Growth Rate | N43: =(N40-(N39/N41))/(1+(N39/N41)) -> 0.073495001
A44: Terminal Value | D44: =+D42*D43 -> 28904.989
A45: Discount Factor | D45: =M26 -> 0.56922592 | F45: Implied Equity Value | I45: =+I39-I40-I41+I42 -> 18874.525 | K45: Implied EV/EBITDA
A46: Present Value of Terminal Value | D46: =+D44*D45 -> 16453.469 | K46: =+F39 -> Enterprise Value | N46: =14503+I40+I41-I42 -> 14334.51
...

Sheet forecasted WC
A1: Timeline | B1: Values | C1: Forecast | D1: Lower Confidence Bound | E1: Upper Confidence Bound
A2: 42460 | B2: -56.63
A3: 42825 | B3: 63.22
A4: 43190 | B4: -26.26
A5: 43555 | B5: -88.69
A6: 43921 | B6: -37.99
A7: 44286 | B7: -74.07
A8: 44651 | B8: 51.75
A9: 45016 | B9: 83.45
A10: 45382 | B10: 146.89 | C10: 146.89 | D10: 146.89 | E10: 146.89
A11: 45747 | C11: =_xlfn.FORECAST.ETS(A11,$B$2:$B$10,$A$2:$A$10,1,1) -> #NAME? | D11: =C11-_xlfn.FORECAST.ETS.CONFINT(A11,$B$2:$B$10,$A$2:$A$10,0.95,1,1) -> #NAME? | E11: =C11+_xlfn.FORECAST.ETS.CONFINT(A11,$B$2:$B$10,$A$2:$A$10,0.95,1,1) -> #NAME?
A12: 46112 | C12: =_xlfn.FORECAST.ETS(A12,$B$2:$B$10,$A$2:$A$10,1,1) -> #NAME? | D12: =C12-_xlfn.FORECAST.ETS.CONFINT(A12,$B$2:$B$10,$A$2:$A$10,0.95,1,1) -> #NAME? | E12: =C12+_xlfn.FORECAST.ETS.CONFINT(A12,$B$2:$B$10,$A$2:$A$10,0.95,1,1) -> #NAME?
A13: 46477 | C13: =_xlfn.FORECAST.ETS(A13,$B$2:$B$10,$A$2:$A$10,1,1) -> #NAME? | D13: =C13-_xlfn.FORECAST.ETS.CONFINT(A13,$B$2:$B$10,$A$2:$A$10,0.95,1,1) -> #NAME? | E13: =C13+_xlfn.FORECAST.ETS.CONFINT(A13,$B$2:$B$10,$A$2:$A$10,0.95,1,1) -> #NAME?
A14: 46843 | C14: =_xlfn.FORECAST.ETS(A14,$B$2:$B$10,$A$2:$A$10,1,1) -> #NAME? | D14: =C14-_xlfn.FORECAST.ETS.CONFINT(A14,$B$2:$B$10,$A$2:$A$10,0.95,1,1) -> #NAME? | E14: =C14+_xlfn.FORECAST.ETS.CONFINT(A14,$B$2:$B$10,$A$2:$A$10,0.95,1,1) -> #NAME?
A15: 47208 | C15: =_xlfn.FORECAST.ETS(A15,$B$2:$B$10,$A$2:$A$10,1,1) -> #NAME? | D15: =C15-_xlfn.FORECAST.ETS.CONFINT(A15,$B$2:$B$10,$A$2:$A$10,0.95,1,1) -> #NAME? | E15: =C15+_xlfn.FORECAST.ETS.CONFINT(A15,$B$2:$B$10,$A$2:$A$10,0.95,1,1) -> #NAME?
A16: 47573 | C16: =_xlfn.FORECAST.ETS(A16,$B$2:$B$10,$A$2:$A$10,1,1) -> #NAME? | D16: =C16-_xlfn.FORECAST.ETS.CONFINT(A16,$B$2:$B$10,$A$2:$A$10,0.95,1,1) -> #NAME? | E16: =C16+_xlfn.FORECAST.ETS.CONFINT(A16,$B$2:$B$10,$A$2:$A$10,0.95,1,1) -> #NAME?
